<?xml version="1.0"?>
<robot name="mobile_robot" xmlns:xacro="http://www.ros.org/wiki/xacro">


<!-- ================= MATERIALS ================= -->
  <material name="white">
    <color rgba="1 1 1 1"/>
  </material>

  <material name="black">
    <color rgba="0.1 0.1 0.1 1"/>
  </material>

  <material name="blue">
    <color rgba="0 0.3 1 1"/>
  </material>

  <!-- ================= BASE ================= -->
  <link name="base_footprint"/>

  <link name="base_link">

    <visual>
      <origin xyz="0 0 0"/>
      <geometry>
        <box size="0.84 0.84 0.30"/>
      </geometry>
      <material name="white"/>
    </visual>

    <collision>
      <origin xyz="0 0 0"/>
      <geometry>
        <box size="0.84 0.84 0.30"/>
      </geometry>
    </collision>

    <inertial>
      <mass value="20.0"/>
      <origin xyz="0 0 0"/>
      <inertia
        ixx="1.0" ixy="0.0" ixz="0.0"
        iyy="1.0" iyz="0.0"
        izz="1.0"/>
    </inertial>

  </link>

  <!-- ================= CAMERA ================= -->
  <link name="camera_link">
    <visual>
      <geometry>
        <box size="0.05 0.05 0.05"/>
      </geometry>
      <material name="blue"/>
    </visual>

    <inertial>
      <mass value="0.2"/>
      <inertia ixx="0.001" ixy="0" ixz="0"
               iyy="0.001" iyz="0"
               izz="0.001"/>
    </inertial>
  </link>

  <!-- ================= WHEELS ================= -->
  <link name="right_wheel_link">
    <visual>
      <geometry>
        <cylinder radius="0.10" length="0.04"/>
      </geometry>
      <origin rpy="1.5707 0 0"/>
      <material name="black"/>
    </visual>

    <collision>
      <geometry>
        <cylinder radius="0.10" length="0.04"/>
      </geometry>
      <origin rpy="1.5707 0 0"/>
    </collision>

    <inertial>
      <mass value="1.0"/>
      <inertia ixx="0.01" ixy="0" ixz="0"
               iyy="0.01" iyz="0"
               izz="0.01"/>
    </inertial>
  </link>

  <link name="left_wheel_link">
    <visual>
      <geometry>
        <cylinder radius="0.10" length="0.04"/>
      </geometry>
      <origin rpy="1.5707 0 0"/>
      <material name="black"/>
    </visual>

    <collision>
      <geometry>
        <cylinder radius="0.10" length="0.04"/>
      </geometry>
      <origin rpy="1.5707 0 0"/>
    </collision>

    <inertial>
      <mass value="1.0"/>
      <inertia ixx="0.01" ixy="0" ixz="0"
               iyy="0.01" iyz="0"
               izz="0.01"/>
    </inertial>
  </link>

  <!-- ================= CASTERS ================= -->
  <link name="caster_front_wheel_link">
    <visual>
      <geometry>
        <sphere radius="0.05"/>
      </geometry>
      <material name="black"/>
    </visual>

    <collision>
      <geometry>
        <sphere radius="0.05"/>
      </geometry>
    </collision>

    <inertial>
      <mass value="0.3"/>
      <inertia ixx="0.001" ixy="0" ixz="0"
               iyy="0.001" iyz="0"
               izz="0.001"/>
    </inertial>
  </link>

  <link name="caster_back_wheel_link">
    <visual>
      <geometry>
        <sphere radius="0.05"/>
      </geometry>
      <material name="black"/>
    </visual>

    <collision>
      <geometry>
        <sphere radius="0.05"/>
      </geometry>
    </collision>

    <inertial>
      <mass value="0.3"/>
      <inertia ixx="0.001" ixy="0" ixz="0"
               iyy="0.001" iyz="0"
               izz="0.001"/>
    </inertial>
  </link>

  <!-- ================= JOINTS ================= -->

  <joint name="base_joint" type="fixed">
    <parent link="base_footprint"/>
    <child link="base_link"/>
    <origin xyz="0 0 0.15"/>
  </joint>

  <joint name="camera_joint" type="fixed">
    <parent link="base_link"/>
    <child link="camera_link"/>
    <origin xyz="0.38 0 0.17"/>
  </joint>

  <joint name="left_wheel_joint" type="continuous">
    <parent link="base_link"/>
    <child link="left_wheel_link"/>
    <origin xyz="0 0.27 -0.10"/>
    <axis xyz="0 1 0"/>
  </joint>

  <joint name="right_wheel_joint" type="continuous">
    <parent link="base_link"/>
    <child link="right_wheel_link"/>
    <origin xyz="0 -0.27 -0.10"/>
    <axis xyz="0 1 0"/>
  </joint>

  <joint name="caster_front_joint" type="fixed">
    <parent link="base_link"/>
    <child link="caster_front_wheel_link"/>
    <origin xyz="0.30 0 -0.15"/>
  </joint>

  <joint name="caster_back_joint" type="fixed">
    <parent link="base_link"/>
    <child link="caster_back_wheel_link"/>
    <origin xyz="-0.30 0 -0.15"/>
  </joint>

</robot>